Workbook

Sheet Overview
A1: NIX — Assessment Overview
A2: Sheet / Section | B2: Total | C2: OK | D2: Finding | E2: Investigate
A3: Web | B3: 177 | C3: =COUNTIF(Web!B3,"OK")+COUNTIF(Web!B4,"OK")+COUNTIF(Web!B5,"OK")+COUNTIF(Web!B6,"OK")+COUNTIF(Web!B7,"OK")+COUNTIF(Web!B8,"OK")+COUNTIF(Web!B9,"OK")+COUNTIF(Web!B10,"OK")+COUNTIF(Web!B11,"OK")+COUNTIF(Web!B12,"OK")+COUNTIF(Web!B13,"OK")+COUNTIF(Web!B14,"OK")+COUNTIF(Web!B15,"OK")+COUNTIF(Web!B16,"OK")+COUNTIF(Web!B17,"OK")+COUNTIF(Web!B20,"OK")+COUNTIF(Web!B21,"OK")+COUNTIF(Web!B22,"OK")+COUNTIF(Web!B23,"OK")+COUNTIF(Web!B24,"OK")+COUNTIF(Web!B25,"OK")+COUNTIF(Web!B26,"OK")+COUNTIF(Web!B27,"OK")+COUNTIF(Web!B30,"OK")+COUNTIF(Web!B31,"OK")+COUNTIF(Web!B32,"OK")+COUNTIF(Web!B33,"OK")+COUNTIF(Web!B34,"OK")+COUNTIF(Web!B35,"OK")+COUNTIF(Web!B36,"OK")+COUNTIF(Web!B37,"OK")+COUNTIF(Web!B38,"OK")+COUNTIF(Web!B39,"OK")+COUNTIF(Web!B40,"OK")+COUNTIF(Web!B41,"OK")+COUNTIF(Web!B42,"OK")+COUNTIF(Web!B43,"OK")+COUNTIF(Web!B44,"OK")+COUNTIF(Web!B45,"OK")+COUNTIF(Web!B46,"OK")+COUNTIF(Web!B47,"OK")+COUNTIF(Web!B48,"OK")+COUNTIF(Web!B49,"OK")+COUNTIF(Web!B52,"OK")+COUNTIF(Web!B53,"OK")+COUNTIF(Web!B54,"OK")+COUNTIF(Web!B55,"OK")+COUNTIF(Web!B56,"OK")+COUNTIF(Web!B57,"OK")+COUNTIF(Web!B58,"OK")+COUNTIF(Web!B59,"OK")+COUNTIF(Web!B60,"OK")+COUNTIF(Web!B61,"OK")+COUNTIF(Web!B62,"OK")+COUNTIF(Web!B63,"OK")+COUNTIF(Web!B64,"OK")+COUNTIF(Web!B67,"OK")+COUNTIF(Web!B68,"OK")+COUNTIF(Web!B69,"OK")+COUNTIF(Web!B70,"OK")+COUNTIF(Web!B71,"OK")+COUNTIF(Web!B72,"OK")+COUNTIF(Web!B73,"OK")+COUNTIF(Web!B74,"OK")+COUNTIF(Web!B75,"OK")+COUNTIF(Web!B76,"OK")+COUNTIF(Web!B77,"OK")+COUNTIF(Web!B78,"OK")+COUNTIF(Web!B81,"OK")+COUNTIF(Web!B82,"OK")+COUNTIF(Web!B83,"OK")+COUNTIF(Web!B84,"OK")+COUNTIF(Web!B85,"OK")+COUNTIF(Web!B86,"OK")+COUNTIF(Web!B87,"OK")+COUNTIF(Web!B88,"OK")+COUNTIF(Web!B89,"OK")+COUNTIF(Web!B90,"OK")+COUNTIF(Web!B91,"OK")+COUNTIF(Web!B92,"OK")+COUNTIF(Web!B93,"OK")+COUNTIF(Web!B94,"OK")+COUNTIF(Web!B95,"OK")+COUNTIF(Web!B96,"OK")+COUNTIF(Web!B97,"OK")+COUNTIF(Web!B98,"OK")+COUNTIF(Web!B99,"OK")+COUNTIF(Web!B100,"OK")+COUNTIF(Web!B101,"OK")+COUNTIF(Web!B102,"OK")+COUNTIF(Web!B103,"OK")+COUNTIF(Web!B104,"OK")+COUNTIF(Web!B105,"OK")+COUNTIF(Web!B106,"OK")+COUNTIF(Web!B107,"OK")+COUNTIF(Web!B108,"OK")+COUNTIF(Web!B109,"OK")+COUNTIF(Web!B112,"OK")+COUNTIF(Web!B113,"OK")+COUNTIF(Web!B114,"OK")+COUNTIF(Web!B115,"OK")+COUNTIF(Web!B116,"OK")+COUNTIF(Web!B117,"OK")+COUNTIF(Web!B118,"OK")+COUNTIF(Web!B119,"OK")+COUNTIF(Web!B120,"OK")+COUNTIF(Web!B121,"OK")+COUNTIF(Web!B124,"OK")+COUNTIF(Web!B125,"OK")+COUNTIF(Web!B126,"OK")+COUNTIF(Web!B127,"OK")+COUNTIF(Web!B128,"OK")+COUNTIF(Web!B129,"OK")+COUNTIF(Web!B130,"OK")+COUNTIF(Web!B133,"OK")+COUNTIF(Web!B134,"OK")+COUNTIF(Web!B135,"OK")+COUNTIF(Web!B136,"OK")+COUNTIF(Web!B137,"OK")+COUNTIF(Web!B138,"OK")+COUNTIF(Web!B139,"OK")+COUNTIF(Web!B142,"OK")+COUNTIF(Web!B143,"OK")+COUNTIF(Web!B144,"OK")+COUNTIF(Web!B145,"OK")+COUNTIF(Web!B146,"OK")+COUNTIF(Web!B147,"OK")+COUNTIF(Web!B148,"OK")+COUNTIF(Web!B149,"OK")+COUNTIF(Web!B150,"OK")+COUNTIF(Web!B153,"OK")+COUNTIF(Web!B154,"OK")+COUNTIF(Web!B155,"OK")+COUNTIF(Web!B156,"OK")+COUNTIF(Web!B157,"OK")+COUNTIF(Web!B158,"OK")+COUNTIF(Web!B159,"OK")+COUNTIF(Web!B160,"OK")+COUNTIF(Web!B161,"OK")+COUNTIF(Web!B162,"OK")+COUNTIF(Web!B165,"OK")+COUNTIF(Web!B166,"OK")+COUNTIF(Web!B167,"OK")+COUNTIF(Web!B168,"OK")+COUNTIF(Web!B169,"OK")+COUNTIF(Web!B170,"OK")+COUNTIF(Web!B171,"OK")+COUNTIF(Web!B174,"OK")+COUNTIF(Web!B175,"OK")+COUNTIF(Web!B176,"OK")+COUNTIF(Web!B177,"OK")+COUNTIF(Web!B178,"OK")+COUNTIF(Web!B179,"OK")+COUNTIF(Web!B180,"OK")+COUNTIF(Web!B181,"OK")+COUNTIF(Web!B182,"OK")+COUNTIF(Web!B185,"OK")+COUNTIF(Web!B186,"OK")+COUNTIF(Web!B187,"OK")+COUNTIF(Web!B188,"OK")+COUNTIF(Web!B189,"OK")+COUNTIF(Web!B190,"OK")+COUNTIF(Web!B191,"OK")+COUNTIF(Web!B192,"OK")+COUNTIF(Web!B193,"OK")+COUNTIF(Web!B194,"OK")+COUNTIF(Web!B197,"OK")+COUNTIF(Web!B198,"OK")+COUNTIF(Web!B199,"OK")+COUNTIF(Web!B200,"OK")+COUNTIF(Web!B201,"OK")+COUNTIF(Web!B204,"OK")+COUNTIF(Web!B205,"OK")+COUNTIF(Web!B206,"OK")+COUNTIF(Web!B207,"OK")+COUNTIF(Web!B208,"OK")+COUNTIF(Web!B209,"OK") -> 0 | D3: =COUNTIF(Web!B3,"Finding")+COUNTIF(Web!B4,"Finding")+COUNTIF(Web!B5,"Finding")+COUNTIF(Web!B6,"Finding")+COUNTIF(Web!B7,"Finding")+COUNTIF(Web!B8,"Finding")+COUNTIF(Web!B9,"Finding")+COUNTIF(Web!B10,"Finding")+COUNTIF(Web!B11,"Finding")+COUNTIF(Web!B12,"Finding")+COUNTIF(Web!B13,"Finding")+COUNTIF(Web!B14,"Finding")+COUNTIF(Web!B15,"Finding")+COUNTIF(Web!B16,"Finding")+COUNTIF(Web!B17,"Finding")+COUNTIF(Web!B20,"Finding")+COUNTIF(Web!B21,"Finding")+COUNTIF(Web!B22,"Finding")+COUNTIF(Web!B23,"Finding")+COUNTIF(Web!B24,"Finding")+COUNTIF(Web!B25,"Finding")+COUNTIF(Web!B26,"Finding")+COUNTIF(Web!B27,"Finding")+COUNTIF(Web!B30,"Finding")+COUNTIF(Web!B31,"Finding")+COUNTIF(Web!B32,"Finding")+COUNTIF(Web!B33,"Finding")+COUNTIF(Web!B34,"Finding")+COUNTIF(Web!B35,"Finding")+COUNTIF(Web!B36,"Finding")+COUNTIF(Web!B37,"Finding")+COUNTIF(Web!B38,"Finding")+COUNTIF(Web!B39,"Finding")+COUNTIF(Web!B40,"Finding")+COUNTIF(Web!B41,"Finding")+COUNTIF(Web!B42,"Finding")+COUNTIF(Web!B43,"Finding")+COUNTIF(Web!B44,"Finding")+COUNTIF(Web!B45,"Finding")+COUNTIF(Web!B46,"Finding")+COUNTIF(Web!B47,"Finding")+COUNTIF(Web!B48,"Finding")+COUNTIF(Web!B49,"Finding")+COUNTIF(Web!B52,"Finding")+COUNTIF(Web!B53,"Finding")+COUNTIF(Web!B54,"Finding")+COUNTIF(Web!B55,"Finding")+COUNTIF(Web!B56,"Finding")+COUNTIF(Web!B57,"Finding")+COUNTIF(Web!B58,"Finding")+COUNTIF(Web!B59,"Finding")+COUNTIF(Web!B60,"Finding")+COUNTIF(Web!B61,"Finding")+COUNTIF(Web!B62,"Finding")+COUNTIF(Web!B63,"Finding")+COUNTIF(Web!B64,"Finding")+COUNTIF(Web!B67,"Finding")+COUNTIF(Web!B68,"Finding")+COUNTIF(Web!B69,"Finding")+COUNTIF(Web!B70,"Finding")+COUNTIF(Web!B71,"Finding")+COUNTIF(Web!B72,"Finding")+COUNTIF(Web!B73,"Finding")+COUNTIF(Web!B74,"Finding")+COUNTIF(Web!B75,"Finding")+COUNTIF(Web!B76,"Finding")+COUNTIF(Web!B77,"Finding")+COUNTIF(Web!B78,"Finding")+COUNTIF(Web!B81,"Finding")+COUNTIF(Web!B82,"Finding")+COUNTIF(Web!B83,"Finding")+COUNTIF(Web!B84,"Finding")+COUNTIF(Web!B85,"Finding")+COUNTIF(Web!B86,"Finding")+COUNTIF(Web!B87,"Finding")+COUNTIF(Web!B88,"Finding")+COUNTIF(Web!B89,"Finding")+COUNTIF(Web!B90,"Finding")+COUNTIF(Web!B91,"Finding")+COUNTIF(Web!B92,"Finding")+COUNTIF(Web!B93,"Finding")+COUNTIF(Web!B94,"Finding")+COUNTIF(Web!B95,"Finding")+COUNTIF(Web!B96,"Finding")+COUNTIF(Web!B97,"Finding")+COUNTIF(Web!B98,"Finding")+COUNTIF(Web!B99,"Finding")+COUNTIF(Web!B100,"Finding")+COUNTIF(Web!B101,"Finding")+COUNTIF(Web!B102,"Finding")+COUNTIF(Web!B103,"Finding")+COUNTIF(Web!B104,"Finding")+COUNTIF(Web!B105,"Finding")+COUNTIF(Web!B106,"Finding")+COUNTIF(Web!B107,"Finding")+COUNTIF(Web!B108,"Finding")+COUNTIF(Web!B109,"Finding")+COUNTIF(Web!B112,"Finding")+COUNTIF(Web!B113,"Finding")+COUNTIF(Web!B114,"Finding")+COUNTIF(Web!B115,"Finding")+COUNTIF(Web!B116,"Finding")+COUNTIF(Web!B117,"Finding")+COUNTIF(Web!B118,"Finding")+COUNTIF(Web!B119,"Finding")+COUNTIF(Web!B120,"Finding")+COUNTIF(Web!B121,"Finding")+COUNTIF(Web!B124,"Finding")+COUNTIF(Web!B125,"Finding")+COUNTIF(Web!B126,"Finding")+COUNTIF(Web!B127,"Finding")+COUNTIF(Web!B128,"Finding")+COUNTIF(Web!B129,"Finding")+COUNTIF(Web!B130,"Finding")+COUNTIF(Web!B133,"Finding")+COUNTIF(Web!B134,"Finding")+COUNTIF(Web!B135,"Finding")+COUNTIF(Web!B136,"Finding")+COUNTIF(Web!B137,"Finding")+COUNTIF(Web!B138,"Finding")+COUNTIF(Web!B139,"Finding")+COUNTIF(Web!B142,"Finding")+COUNTIF(Web!B143,"Finding")+COUNTIF(Web!B144,"Finding")+COUNTIF(Web!B145,"Finding")+COUNTIF(Web!B146,"Finding")+COUNTIF(Web!B147,"Finding")+COUNTIF(Web!B148,"Finding")+COUNTIF(Web!B149,"Finding")+COUNTIF(Web!B150,"Finding")+COUNTIF(Web!B153,"Finding")+COUNTIF(Web!B154,"Finding")+COUNTIF(Web!B155,"Finding")+COUNTIF(Web!B156,"Finding")+COUNTIF(Web!B157,"Finding")+COUNTIF(Web!B158,"Finding")+COUNTIF(Web!B159,"Finding")+COUNTIF(Web!B160,"Finding")+COUNTIF(Web!B161,"Finding")+COUNTIF(Web!B162,"Finding")+COUNTIF(Web!B165,"Finding")+COUNTIF(Web!B166,"Finding")+COUNTIF(Web!B167,"Finding")+COUNTIF(Web!B168,"Finding")+COUNTIF(Web!B169,"Finding")+COUNTIF(Web!B170,"Finding")+COUNTIF(Web!B171,"Finding")+COUNTIF(Web!B174,"Finding")+COUNTIF(Web!B175,"Finding")+COUNTIF(Web!B176,"Finding")+COUNTIF(Web!B177,"Finding")+COUNTIF(Web!B178,"Finding")+COUNTIF(Web!B179,"Finding")+COUNTIF(Web!B180,"Finding")+COUNTIF(Web!B181,"Finding")+COUNTIF(Web!B182,"Finding")+COUNTIF(Web!B185,"Finding")+COUNTIF(Web!B186,"Finding")+COUNTIF(Web!B187,"Finding")+COUNTIF(Web!B188,"Finding")+COUNTIF(Web!B189,"Finding")+COUNTIF(Web!B190,"Finding")+COUNTIF(Web!B191,"Finding")+COUNTIF(Web!B192,"Finding")+COUNTIF(Web!B193,"Finding")+COUNTIF(Web!B194,"Finding")+COUNTIF(Web!B197,"Finding")+COUNTIF(Web!B198,"Finding")+COUNTIF(Web!B199,"Finding")+COUNTIF(Web!B200,"Finding")+COUNTIF(Web!B201,"Finding")+COUNTIF(Web!B204,"Finding")+COUNTIF(Web!B205,"Finding")+COUNTIF(Web!B206,"Finding")+COUNTIF(Web!B207,"Finding")+COUNTIF(Web!B208,"Finding")+COUNTIF(Web!B209,"Finding") -> 0 | E3: =COUNTIF(Web!B3,"Investigate")+COUNTIF(Web!B4,"Investigate")+COUNTIF(Web!B5,"Investigate")+COUNTIF(Web!B6,"Investigate")+COUNTIF(Web!B7,"Investigate")+COUNTIF(Web!B8,"Investigate")+COUNTIF(Web!B9,"Investigate")+COUNTIF(Web!B10,"Investigate")+COUNTIF(Web!B11,"Investigate")+COUNTIF(Web!B12,"Investigate")+COUNTIF(Web!B13,"Investigate")+COUNTIF(Web!B14,"Investigate")+COUNTIF(Web!B15,"Investigate")+COUNTIF(Web!B16,"Investigate")+COUNTIF(Web!B17,"Investigate")+COUNTIF(Web!B20,"Investigate")+COUNTIF(Web!B21,"Investigate")+COUNTIF(Web!B22,"Investigate")+COUNTIF(Web!B23,"Investigate")+COUNTIF(Web!B24,"Investigate")+COUNTIF(Web!B25,"Investigate")+COUNTIF(Web!B26,"Investigate")+COUNTIF(Web!B27,"Investigate")+COUNTIF(Web!B30,"Investigate")+COUNTIF(Web!B31,"Investigate")+COUNTIF(Web!B32,"Investigate")+COUNTIF(Web!B33,"Investigate")+COUNTIF(Web!B34,"Investigate")+COUNTIF(Web!B35,"Investigate")+COUNTIF(Web!B36,"Investigate")+COUNTIF(Web!B37,"Investigate")+COUNTIF(Web!B38,"Investigate")+COUNTIF(Web!B39,"Investigate")+COUNTIF(Web!B40,"Investigate")+COUNTIF(Web!B41,"Investigate")+COUNTIF(Web!B42,"Investigate")+COUNTIF(Web!B43,"Investigate")+COUNTIF(Web!B44,"Investigate")+COUNTIF(Web!B45,"Investigate")+COUNTIF(Web!B46,"Investigate")+COUNTIF(Web!B47,"Investigate")+COUNTIF(Web!B48,"Investigate")+COUNTIF(Web!B49,"Investigate")+COUNTIF(Web!B52,"Investigate")+COUNTIF(Web!B53,"Investigate")+COUNTIF(Web!B54,"Investigate")+COUNTIF(Web!B55,"Investigate")+COUNTIF(Web!B56,"Investigate")+COUNTIF(Web!B57,"Investigate")+COUNTIF(Web!B58,"Investigate")+COUNTIF(Web!B59,"Investigate")+COUNTIF(Web!B60,"Investigate")+COUNTIF(Web!B61,"Investigate")+COUNTIF(Web!B62,"Investigate")+COUNTIF(Web!B63,"Investigate")+COUNTIF(Web!B64,"Investigate")+COUNTIF(Web!B67,"Investigate")+COUNTIF(Web!B68,"Investigate")+COUNTIF(Web!B69,"Investigate")+COUNTIF(Web!B70,"Investigate")+COUNTIF(Web!B71,"Investigate")+COUNTIF(Web!B72,"Investigate")+COUNTIF(Web!B73,"Investigate")+COUNTIF(Web!B74,"Investigate")+COUNTIF(Web!B75,"Investigate")+COUNTIF(Web!B76,"Investigate")+COUNTIF(Web!B77,"Investigate")+COUNTIF(Web!B78,"Investigate")+COUNTIF(Web!B81,"Investigate")+COUNTIF(Web!B82,"Investigate")+COUNTIF(Web!B83,"Investigate")+COUNTIF(Web!B84,"Investigate")+COUNTIF(Web!B85,"Investigate")+COUNTIF(Web!B86,"Investigate")+COUNTIF(Web!B87,"Investigate")+COUNTIF(Web!B88,"Investigate")+COUNTIF(Web!B89,"Investigate")+COUNTIF(Web!B90,"Investigate")+COUNTIF(Web!B91,"Investigate")+COUNTIF(Web!B92,"Investigate")+COUNTIF(Web!B93,"Investigate")+COUNTIF(Web!B94,"Investigate")+COUNTIF(Web!B95,"Investigate")+COUNTIF(Web!B96,"Investigate")+COUNTIF(Web!B97,"Investigate")+COUNTIF(Web!B98,"Investigate")+COUNTIF(Web!B99,"Investigate")+COUNTIF(Web!B100,"Investigate")+COUNTIF(Web!B101,"Investigate")+COUNTIF(Web!B102,"Investigate")+COUNTIF(Web!B103,"Investigate")+COUNTIF(Web!B104,"Investigate")+COUNTIF(Web!B105,"Investigate")+COUNTIF(Web!B106,"Investigate")+COUNTIF(Web!B107,"Investigate")+COUNTIF(Web!B108,"Investigate")+COUNTIF(Web!B109,"Investigate")+COUNTIF(Web!B112,"Investigate")+COUNTIF(Web!B113,"Investigate")+COUNTIF(Web!B114,"Investigate")+COUNTIF(Web!B115,"Investigate")+COUNTIF(Web!B116,"Investigate")+COUNTIF(Web!B117,"Investigate")+COUNTIF(Web!B118,"Investigate")+COUNTIF(Web!B119,"Investigate")+COUNTIF(Web!B120,"Investigate")+COUNTIF(Web!B121,"Investigate")+COUNTIF(Web!B124,"Investigate")+COUNTIF(Web!B125,"Investigate")+COUNTIF(Web!B126,"Investigate")+COUNTIF(Web!B127,"Investigate")+COUNTIF(Web!B128,"Investigate")+COUNTIF(Web!B129,"Investigate")+COUNTIF(Web!B130,"Investigate")+COUNTIF(Web!B133,"Investigate")+COUNTIF(Web!B134,"Investigate")+COUNTIF(Web!B135,"Investigate")+COUNTIF(Web!B136,"Investigate")+COUNTIF(Web!B137,"Investigate")+COUNTIF(Web!B138,"Investigate")+COUNTIF(Web!B139,"Investigate")+COUNTIF(Web!B142,"Investigate")+COUNTIF(Web!B143,"Investigate")+COUNTIF(Web!B144,"Investigate")+COUNTIF(Web!B145,"Investigate")+COUNTIF(Web!B146,"Investigate")+COUNTIF(Web!B147,"Investigate")+COUNTIF(Web!B148,"Investigate")+COUNTIF(Web!B149,"Investigate")+COUNTIF(Web!B150,"Investigate")+COUNTIF(Web!B153,"Investigate")+COUNTIF(Web!B154,"Investigate")+COUNTIF(Web!B155,"Investigate")+COUNTIF(Web!B156,"Investigate")+COUNTIF(Web!B157,"Investigate")+COUNTIF(Web!B158,"Investigate")+COUNTIF(Web!B159,"Investigate")+COUNTIF(Web!B160,"Investigate")+COUNTIF(Web!B161,"Investigate")+COUNTIF(Web!B162,"Investigate")+COUNTIF(Web!B165,"Investigate")+COUNTIF(Web!B166,"Investigate")+COUNTIF(Web!B167,"Investigate")+COUNTIF(Web!B168,"Investigate")+COUNTIF(Web!B169,"Investigate")+COUNTIF(Web!B170,"Investigate")+COUNTIF(Web!B171,"Investigate")+COUNTIF(Web!B174,"Investigate")+COUNTIF(Web!B175,"Investigate")+COUNTIF(Web!B176,"Investigate")+COUNTIF(Web!B177,"Investigate")+COUNTIF(Web!B178,"Investigate")+COUNTIF(Web!B179,"Investigate")+COUNTIF(Web!B180,"Investigate")+COUNTIF(Web!B181,"Investigate")+COUNTIF(Web!B182,"Investigate")+COUNTIF(Web!B185,"Investigate")+COUNTIF(Web!B186,"Investigate")+COUNTIF(Web!B187,"Investigate")+COUNTIF(Web!B188,"Investigate")+COUNTIF(Web!B189,"Investigate")+COUNTIF(Web!B190,"Investigate")+COUNTIF(Web!B191,"Investigate")+COUNTIF(Web!B192,"Investigate")+COUNTIF(Web!B193,"Investigate")+COUNTIF(Web!B194,"Investigate")+COUNTIF(Web!B197,"Investigate")+COUNTIF(Web!B198,"Investigate")+COUNTIF(Web!B199,"Investigate")+COUNTIF(Web!B200,"Investigate")+COUNTIF(Web!B201,"Investigate")+COUNTIF(Web!B204,"Investigate")+COUNTIF(Web!B205,"Investigate")+COUNTIF(Web!B206,"Investigate")+COUNTIF(Web!B207,"Investigate")+COUNTIF(Web!B208,"Investigate")+COUNTIF(Web!B209,"Investigate") -> 0
A4: Reconnaissance & Scope Mapping | B4: 15 | C4: =COUNTIF(Web!B3,"OK")+COUNTIF(Web!B4,"OK")+COUNTIF(Web!B5,"OK")+COUNTIF(Web!B6,"OK")+COUNTIF(Web!B7,"OK")+COUNTIF(Web!B8,"OK")+COUNTIF(Web!B9,"OK")+COUNTIF(Web!B10,"OK")+COUNTIF(Web!B11,"OK")+COUNTIF(Web!B12,"OK")+COUNTIF(Web!B13,"OK")+COUNTIF(Web!B14,"OK")+COUNTIF(Web!B15,"OK")+COUNTIF(Web!B16,"OK")+COUNTIF(Web!B17,"OK") -> 0 | D4: =COUNTIF(Web!B3,"Finding")+COUNTIF(Web!B4,"Finding")+COUNTIF(Web!B5,"Finding")+COUNTIF(Web!B6,"Finding")+COUNTIF(Web!B7,"Finding")+COUNTIF(Web!B8,"Finding")+COUNTIF(Web!B9,"Finding")+COUNTIF(Web!B10,"Finding")+COUNTIF(Web!B11,"Finding")+COUNTIF(Web!B12,"Finding")+COUNTIF(Web!B13,"Finding")+COUNTIF(Web!B14,"Finding")+COUNTIF(Web!B15,"Finding")+COUNTIF(Web!B16,"Finding")+COUNTIF(Web!B17,"Finding") -> 0 | E4: =COUNTIF(Web!B3,"Investigate")+COUNTIF(Web!B4,"Investigate")+COUNTIF(Web!B5,"Investigate")+COUNTIF(Web!B6,"Investigate")+COUNTIF(Web!B7,"Investigate")+COUNTIF(Web!B8,"Investigate")+COUNTIF(Web!B9,"Investigate")+COUNTIF(Web!B10,"Investigate")+COUNTIF(Web!B11,"Investigate")+COUNTIF(Web!B12,"Investigate")+COUNTIF(Web!B13,"Investigate")+COUNTIF(Web!B14,"Investigate")+COUNTIF(Web!B15,"Investigate")+COUNTIF(Web!B16,"Investigate")+COUNTIF(Web!B17,"Investigate") -> 0
A5: Technology Fingerprinting | B5: 8 | C5: =COUNTIF(Web!B20,"OK")+COUNTIF(Web!B21,"OK")+COUNTIF(Web!B22,"OK")+COUNTIF(Web!B23,"OK")+COUNTIF(Web!B24,"OK")+COUNTIF(Web!B25,"OK")+COUNTIF(Web!B26,"OK")+COUNTIF(Web!B27,"OK") -> 0 | D5: =COUNTIF(Web!B20,"Finding")+COUNTIF(Web!B21,"Finding")+COUNTIF(Web!B22,"Finding")+COUNTIF(Web!B23,"Finding")+COUNTIF(Web!B24,"Finding")+COUNTIF(Web!B25,"Finding")+COUNTIF(Web!B26,"Finding")+COUNTIF(Web!B27,"Finding") -> 0 | E5: =COUNTIF(Web!B20,"Investigate")+COUNTIF(Web!B21,"Investigate")+COUNTIF(Web!B22,"Investigate")+COUNTIF(Web!B23,"Investigate")+COUNTIF(Web!B24,"Investigate")+COUNTIF(Web!B25,"Investigate")+COUNTIF(Web!B26,"Investigate")+COUNTIF(Web!B27,"Investigate") -> 0
A6: Authentication | B6: 20 | C6: =COUNTIF(Web!B30,"OK")+COUNTIF(Web!B31,"OK")+COUNTIF(Web!B32,"OK")+COUNTIF(Web!B33,"OK")+COUNTIF(Web!B34,"OK")+COUNTIF(Web!B35,"OK")+COUNTIF(Web!B36,"OK")+COUNTIF(Web!B37,"OK")+COUNTIF(Web!B38,"OK")+COUNTIF(Web!B39,"OK")+COUNTIF(Web!B40,"OK")+COUNTIF(Web!B41,"OK")+COUNTIF(Web!B42,"OK")+COUNTIF(Web!B43,"OK")+COUNTIF(Web!B44,"OK")+COUNTIF(Web!B45,"OK")+COUNTIF(Web!B46,"OK")+COUNTIF(Web!B47,"OK")+COUNTIF(Web!B48,"OK")+COUNTIF(Web!B49,"OK") -> 0 | D6: =COUNTIF(Web!B30,"Finding")+COUNTIF(Web!B31,"Finding")+COUNTIF(Web!B32,"Finding")+COUNTIF(Web!B33,"Finding")+COUNTIF(Web!B34,"Finding")+COUNTIF(Web!B35,"Finding")+COUNTIF(Web!B36,"Finding")+COUNTIF(Web!B37,"Finding")+COUNTIF(Web!B38,"Finding")+COUNTIF(Web!B39,"Finding")+COUNTIF(Web!B40,"Finding")+COUNTIF(Web!B41,"Finding")+COUNTIF(Web!B42,"Finding")+COUNTIF(Web!B43,"Finding")+COUNTIF(Web!B44,"Finding")+COUNTIF(Web!B45,"Finding")+COUNTIF(Web!B46,"Finding")+COUNTIF(Web!B47,"Finding")+COUNTIF(Web!B48,"Finding")+COUNTIF(Web!B49,"Finding") -> 0 | E6: =COUNTIF(Web!B30,"Investigate")+COUNTIF(Web!B31,"Investigate")+COUNTIF(Web!B32,"Investigate")+COUNTIF(Web!B33,"Investigate")+COUNTIF(Web!B34,"Investigate")+COUNTIF(Web!B35,"Investigate")+COUNTIF(Web!B36,"Investigate")+COUNTIF(Web!B37,"Investigate")+COUNTIF(Web!B38,"Investigate")+COUNTIF(Web!B39,"Investigate")+COUNTIF(Web!B40,"Investigate")+COUNTIF(Web!B41,"Investigate")+COUNTIF(Web!B42,"Investigate")+COUNTIF(Web!B43,"Investigate")+COUNTIF(Web!B44,"Investigate")+COUNTIF(Web!B45,"Investigate")+COUNTIF(Web!B46,"Investigate")+COUNTIF(Web!B47,"Investigate")+COUNTIF(Web!B48,"Investigate")+COUNTIF(Web!B49,"Investigate") -> 0
A7: Session Management | B7: 13 | C7: =COUNTIF(Web!B52,"OK")+COUNTIF(Web!B53,"OK")+COUNTIF(Web!B54,"OK")+COUNTIF(Web!B55,"OK")+COUNTIF(Web!B56,"OK")+COUNTIF(Web!B57,"OK")+COUNTIF(Web!B58,"OK")+COUNTIF(Web!B59,"OK")+COUNTIF(Web!B60,"OK")+COUNTIF(Web!B61,"OK")+COUNTIF(Web!B62,"OK")+COUNTIF(Web!B63,"OK")+COUNTIF(Web!B64,"OK") -> 0 | D7: =COUNTIF(Web!B52,"Finding")+COUNTIF(Web!B53,"Finding")+COUNTIF(Web!B54,"Finding")+COUNTIF(Web!B55,"Finding")+COUNTIF(Web!B56,"Finding")+COUNTIF(Web!B57,"Finding")+COUNTIF(Web!B58,"Finding")+COUNTIF(Web!B59,"Finding")+COUNTIF(Web!B60,"Finding")+COUNTIF(Web!B61,"Finding")+COUNTIF(Web!B62,"Finding")+COUNTIF(Web!B63,"Finding")+COUNTIF(Web!B64,"Finding") -> 0 | E7: =COUNTIF(Web!B52,"Investigate")+COUNTIF(Web!B53,"Investigate")+COUNTIF(Web!B54,"Investigate")+COUNTIF(Web!B55,"Investigate")+COUNTIF(Web!B56,"Investigate")+COUNTIF(Web!B57,"Investigate")+COUNTIF(Web!B58,"Investigate")+COUNTIF(Web!B59,"Investigate")+COUNTIF(Web!B60,"Investigate")+COUNTIF(Web!B61,"Investigate")+COUNTIF(Web!B62,"Investigate")+COUNTIF(Web!B63,"Investigate")+COUNTIF(Web!B64,"Investigate") -> 0
A8: Authorisation & Access Control | B8: 12 | C8: =COUNTIF(Web!B67,"OK")+COUNTIF(Web!B68,"OK")+COUNTIF(Web!B69,"OK")+COUNTIF(Web!B70,"OK")+COUNTIF(Web!B71,"OK")+COUNTIF(Web!B72,"OK")+COUNTIF(Web!B73,"OK")+COUNTIF(Web!B74,"OK")+COUNTIF(Web!B75,"OK")+COUNTIF(Web!B76,"OK")+COUNTIF(Web!B77,"OK")+COUNTIF(Web!B78,"OK") -> 0 | D8: =COUNTIF(Web!B67,"Finding")+COUNTIF(Web!B68,"Finding")+COUNTIF(Web!B69,"Finding")+COUNTIF(Web!B70,"Finding")+COUNTIF(Web!B71,"Finding")+COUNTIF(Web!B72,"Finding")+COUNTIF(Web!B73,"Finding")+COUNTIF(Web!B74,"Finding")+COUNTIF(Web!B75,"Finding")+COUNTIF(Web!B76,"Finding")+COUNTIF(Web!B77,"Finding")+COUNTIF(Web!B78,"Finding") -> 0 | E8: =COUNTIF(Web!B67,"Investigate")+COUNTIF(Web!B68,"Investigate")+COUNTIF(Web!B69,"Investigate")+COUNTIF(Web!B70,"Investigate")+COUNTIF(Web!B71,"Investigate")+COUNTIF(Web!B72,"Investigate")+COUNTIF(Web!B73,"Investigate")+COUNTIF(Web!B74,"Investigate")+COUNTIF(Web!B75,"Investigate")+COUNTIF(Web!B76,"Investigate")+COUNTIF(Web!B77,"Investigate")+COUNTIF(Web!B78,"Investigate") -> 0
A9: Input Validation & Injection | B9: 29 | C9: =COUNTIF(Web!B81,"OK")+COUNTIF(Web!B82,"OK")+COUNTIF(Web!B83,"OK")+COUNTIF(Web!B84,"OK")+COUNTIF(Web!B85,"OK")+COUNTIF(Web!B86,"OK")+COUNTIF(Web!B87,"OK")+COUNTIF(Web!B88,"OK")+COUNTIF(Web!B89,"OK")+COUNTIF(Web!B90,"OK")+COUNTIF(Web!B91,"OK")+COUNTIF(Web!B92,"OK")+COUNTIF(Web!B93,"OK")+COUNTIF(Web!B94,"OK")+COUNTIF(Web!B95,"OK")+COUNTIF(Web!B96,"OK")+COUNTIF(Web!B97,"OK")+COUNTIF(Web!B98,"OK")+COUNTIF(Web!B99,"OK")+COUNTIF(Web!B100,"OK")+COUNTIF(Web!B101,"OK")+COUNTIF(Web!B102,"OK")+COUNTIF(Web!B103,"OK")+COUNTIF(Web!B104,"OK")+COUNTIF(Web!B105,"OK")+COUNTIF(Web!B106,"OK")+COUNTIF(Web!B107,"OK")+COUNTIF(Web!B108,"OK")+COUNTIF(Web!B109,"OK") -> 0 | D9: =COUNTIF(Web!B81,"Finding")+COUNTIF(Web!B82,"Finding")+COUNTIF(Web!B83,"Finding")+COUNTIF(Web!B84,"Finding")+COUNTIF(Web!B85,"Finding")+COUNTIF(Web!B86,"Finding")+COUNTIF(Web!B87,"Finding")+COUNTIF(Web!B88,"Finding")+COUNTIF(Web!B89,"Finding")+COUNTIF(Web!B90,"Finding")+COUNTIF(Web!B91,"Finding")+COUNTIF(Web!B92,"Finding")+COUNTIF(Web!B93,"Finding")+COUNTIF(Web!B94,"Finding")+COUNTIF(Web!B95,"Finding")+COUNTIF(Web!B96,"Finding")+COUNTIF(Web!B97,"Finding")+COUNTIF(Web!B98,"Finding")+COUNTIF(Web!B99,"Finding")+COUNTIF(Web!B100,"Finding")+COUNTIF(Web!B101,"Finding")+COUNTIF(Web!B102,"Finding")+COUNTIF(Web!B103,"Finding")+COUNTIF(Web!B104,"Finding")+COUNTIF(Web!B105,"Finding")+COUNTIF(Web!B106,"Finding")+COUNTIF(Web!B107,"Finding")+COUNTIF(Web!B108,"Finding")+COUNTIF(Web!B109,"Finding") -> 0 | E9: =COUNTIF(Web!B81,"Investigate")+COUNTIF(Web!B82,"Investigate")+COUNTIF(Web!B83,"Investigate")+COUNTIF(Web!B84,"Investigate")+COUNTIF(Web!B85,"Investigate")+COUNTIF(Web!B86,"Investigate")+COUNTIF(Web!B87,"Investigate")+COUNTIF(Web!B88,"Investigate")+COUNTIF(Web!B89,"Investigate")+COUNTIF(Web!B90,"Investigate")+COUNTIF(Web!B91,"Investigate")+COUNTIF(Web!B92,"Investigate")+COUNTIF(Web!B93,"Investigate")+COUNTIF(Web!B94,"Investigate")+COUNTIF(Web!B95,"Investigate")+COUNTIF(Web!B96,"Investigate")+COUNTIF(Web!B97,"Investigate")+COUNTIF(Web!B98,"Investigate")+COUNTIF(Web!B99,"Investigate")+COUNTIF(Web!B100,"Investigate")+COUNTIF(Web!B101,"Investigate")+COUNTIF(Web!B102,"Investigate")+COUNTIF(Web!B103,"Investigate")+COUNTIF(Web!B104,"Investigate")+COUNTIF(Web!B105,"Investigate")+COUNTIF(Web!B106,"Investigate")+COUNTIF(Web!B107,"Investigate")+COUNTIF(Web!B108,"Investigate")+COUNTIF(Web!B109,"Investigate") -> 0
A10: File Upload | B10: 10 | C10: =COUNTIF(Web!B112,"OK")+COUNTIF(Web!B113,"OK")+COUNTIF(Web!B114,"OK")+COUNTIF(Web!B115,"OK")+COUNTIF(Web!B116,"OK")+COUNTIF(Web!B117,"OK")+COUNTIF(Web!B118,"OK")+COUNTIF(Web!B119,"OK")+COUNTIF(Web!B120,"OK")+COUNTIF(Web!B121,"OK") -> 0 | D10: =COUNTIF(Web!B112,"Finding")+COUNTIF(Web!B113,"Finding")+COUNTIF(Web!B114,"Finding")+COUNTIF(Web!B115,"Finding")+COUNTIF(Web!B116,"Finding")+COUNTIF(Web!B117,"Finding")+COUNTIF(Web!B118,"Finding")+COUNTIF(Web!B119,"Finding")+COUNTIF(Web!B120,"Finding")+COUNTIF(Web!B121,"Finding") -> 0 | E10: =COUNTIF(Web!B112,"Investigate")+COUNTIF(Web!B113,"Investigate")+COUNTIF(Web!B114,"Investigate")+COUNTIF(Web!B115,"Investigate")+COUNTIF(Web!B116,"Investigate")+COUNTIF(Web!B117,"Investigate")+COUNTIF(Web!B118,"Investigate")+COUNTIF(Web!B119,"Investigate")+COUNTIF(Web!B120,"Investigate")+COUNTIF(Web!B121,"Investigate") -> 0
A11: Cross-Site Request Forgery (CSRF) | B11: 7 | C11: =COUNTIF(Web!B124,"OK")+COUNTIF(Web!B125,"OK")+COUNTIF(Web!B126,"OK")+COUNTIF(Web!B127,"OK")+COUNTIF(Web!B128,"OK")+COUNTIF(Web!B129,"OK")+COUNTIF(Web!B130,"OK") -> 0 | D11: =COUNTIF(Web!B124,"Finding")+COUNTIF(Web!B125,"Finding")+COUNTIF(Web!B126,"Finding")+COUNTIF(Web!B127,"Finding")+COUNTIF(Web!B128,"Finding")+COUNTIF(Web!B129,"Finding")+COUNTIF(Web!B130,"Finding") -> 0 | E11: =COUNTIF(Web!B124,"Investigate")+COUNTIF(Web!B125,"Investigate")+COUNTIF(Web!B126,"Investigate")+COUNTIF(Web!B127,"Investigate")+COUNTIF(Web!B128,"Investigate")+COUNTIF(Web!B129,"Investigate")+COUNTIF(Web!B130,"Investigate") -> 0
A12: Server-Side Request Forgery (SSRF) | B12: 7 | C12: =COUNTIF(Web!B133,"OK")+COUNTIF(Web!B134,"OK")+COUNTIF(Web!B135,"OK")+COUNTIF(Web!B136,"OK")+COUNTIF(Web!B137,"OK")+COUNTIF(Web!B138,"OK")+COUNTIF(Web!B139,"OK") -> 0 | D12: =COUNTIF(Web!B133,"Finding")+COUNTIF(Web!B134,"Finding")+COUNTIF(Web!B135,"Finding")+COUNTIF(Web!B136,"Finding")+COUNTIF(Web!B137,"Finding")+COUNTIF(Web!B138,"Finding")+COUNTIF(Web!B139,"Finding") -> 0 | E12: =COUNTIF(Web!B133,"Investigate")+COUNTIF(Web!B134,"Investigate")+COUNTIF(Web!B135,"Investigate")+COUNTIF(Web!B136,"Investigate")+COUNTIF(Web!B137,"Investigate")+COUNTIF(Web!B138,"Investigate")+COUNTIF(Web!B139,"Investigate") -> 0
A13: Business Logic | B13: 9 | C13: =COUNTIF(Web!B142,"OK")+COUNTIF(Web!B143,"OK")+COUNTIF(Web!B144,"OK")+COUNTIF(Web!B145,"OK")+COUNTIF(Web!B146,"OK")+COUNTIF(Web!B147,"OK")+COUNTIF(Web!B148,"OK")+COUNTIF(Web!B149,"OK")+COUNTIF(Web!B150,"OK") -> 0 | D13: =COUNTIF(Web!B142,"Finding")+COUNTIF(Web!B143,"Finding")+COUNTIF(Web!B144,"Finding")+COUNTIF(Web!B145,"Finding")+COUNTIF(Web!B146,"Finding")+COUNTIF(Web!B147,"Finding")+COUNTIF(Web!B148,"Finding")+COUNTIF(Web!B149,"Finding")+COUNTIF(Web!B150,"Finding") -> 0 | E13: =COUNTIF(Web!B142,"Investigate")+COUNTIF(Web!B143,"Investigate")+COUNTIF(Web!B144,"Investigate")+COUNTIF(Web!B145,"Investigate")+COUNTIF(Web!B146,"Investigate")+COUNTIF(Web!B147,"Investigate")+COUNTIF(Web!B148,"Investigate")+COUNTIF(Web!B149,"Investigate")+COUNTIF(Web!B150,"Investigate") -> 0
A14: API Testing | B14: 10 | C14: =COUNTIF(Web!B153,"OK")+COUNTIF(Web!B154,"OK")+COUNTIF(Web!B155,"OK")+COUNTIF(Web!B156,"OK")+COUNTIF(Web!B157,"OK")+COUNTIF(Web!B158,"OK")+COUNTIF(Web!B159,"OK")+COUNTIF(Web!B160,"OK")+COUNTIF(Web!B161,"OK")+COUNTIF(Web!B162,"OK") -> 0 | D14: =COUNTIF(Web!B153,"Finding")+COUNTIF(Web!B154,"Finding")+COUNTIF(Web!B155,"Finding")+COUNTIF(Web!B156,"Finding")+COUNTIF(Web!B157,"Finding")+COUNTIF(Web!B158,"Finding")+COUNTIF(Web!B159,"Finding")+COUNTIF(Web!B160,"Finding")+COUNTIF(Web!B161,"Finding")+COUNTIF(Web!B162,"Finding") -> 0 | E14: =COUNTIF(Web!B153,"Investigate")+COUNTIF(Web!B154,"Investigate")+COUNTIF(Web!B155,"Investigate")+COUNTIF(Web!B156,"Investigate")+COUNTIF(Web!B157,"Investigate")+COUNTIF(Web!B158,"Investigate")+COUNTIF(Web!B159,"Investigate")+COUNTIF(Web!B160,"Investigate")+COUNTIF(Web!B161,"Investigate")+COUNTIF(Web!B162,"Investigate") -> 0
A15: Cryptography & Transport Security | B15: 7 | C15: =COUNTIF(Web!B165,"OK")+COUNTIF(Web!B166,"OK")+COUNTIF(Web!B167,"OK")+COUNTIF(Web!B168,"OK")+COUNTIF(Web!B169,"OK")+COUNTIF(Web!B170,"OK")+COUNTIF(Web!B171,"OK") -> 0 | D15: =COUNTIF(Web!B165,"Finding")+COUNTIF(Web!B166,"Finding")+COUNTIF(Web!B167,"Finding")+COUNTIF(Web!B168,"Finding")+COUNTIF(Web!B169,"Finding")+COUNTIF(Web!B170,"Finding")+COUNTIF(Web!B171,"Finding") -> 0 | E15: =COUNTIF(Web!B165,"Investigate")+COUNTIF(Web!B166,"Investigate")+COUNTIF(Web!B167,"Investigate")+COUNTIF(Web!B168,"Investigate")+COUNTIF(Web!B169,"Investigate")+COUNTIF(Web!B170,"Investigate")+COUNTIF(Web!B171,"Investigate") -> 0
A16: Information Disclosure | B16: 9 | C16: =COUNTIF(Web!B174,"OK")+COUNTIF(Web!B175,"OK")+COUNTIF(Web!B176,"OK")+COUNTIF(Web!B177,"OK")+COUNTIF(Web!B178,"OK")+COUNTIF(Web!B179,"OK")+COUNTIF(Web!B180,"OK")+COUNTIF(Web!B181,"OK")+COUNTIF(Web!B182,"OK") -> 0 | D16: =COUNTIF(Web!B174,"Finding")+COUNTIF(Web!B175,"Finding")+COUNTIF(Web!B176,"Finding")+COUNTIF(Web!B177,"Finding")+COUNTIF(Web!B178,"Finding")+COUNTIF(Web!B179,"Finding")+COUNTIF(Web!B180,"Finding")+COUNTIF(Web!B181,"Finding")+COUNTIF(Web!B182,"Finding") -> 0 | E16: =COUNTIF(Web!B174,"Investigate")+COUNTIF(Web!B175,"Investigate")+COUNTIF(Web!B176,"Investigate")+COUNTIF(Web!B177,"Investigate")+COUNTIF(Web!B178,"Investigate")+COUNTIF(Web!B179,"Investigate")+COUNTIF(Web!B180,"Investigate")+COUNTIF(Web!B181,"Investigate")+COUNTIF(Web!B182,"Investigate") -> 0
A17: HTTP Headers & Security Misconfigurations | B17: 10 | C17: =COUNTIF(Web!B185,"OK")+COUNTIF(Web!B186,"OK")+COUNTIF(Web!B187,"OK")+COUNTIF(Web!B188,"OK")+COUNTIF(Web!B189,"OK")+COUNTIF(Web!B190,"OK")+COUNTIF(Web!B191,"OK")+COUNTIF(Web!B192,"OK")+COUNTIF(Web!B193,"OK")+COUNTIF(Web!B194,"OK") -> 0 | D17: =COUNTIF(Web!B185,"Finding")+COUNTIF(Web!B186,"Finding")+COUNTIF(Web!B187,"Finding")+COUNTIF(Web!B188,"Finding")+COUNTIF(Web!B189,"Finding")+COUNTIF(Web!B190,"Finding")+COUNTIF(Web!B191,"Finding")+COUNTIF(Web!B192,"Finding")+COUNTIF(Web!B193,"Finding")+COUNTIF(Web!B194,"Finding") -> 0 | E17: =COUNTIF(Web!B185,"Investigate")+COUNTIF(Web!B186,"Investigate")+COUNTIF(Web!B187,"Investigate")+COUNTIF(Web!B188,"Investigate")+COUNTIF(Web!B189,"Investigate")+COUNTIF(Web!B190,"Investigate")+COUNTIF(Web!B191,"Investigate")+COUNTIF(Web!B192,"Investigate")+COUNTIF(Web!B193,"Investigate")+COUNTIF(Web!B194,"Investigate") -> 0
A18: Rate Limiting & DoS | B18: 5 | C18: =COUNTIF(Web!B197,"OK")+COUNTIF(Web!B198,"OK")+COUNTIF(Web!B199,"OK")+COUNTIF(Web!B200,"OK")+COUNTIF(Web!B201,"OK") -> 0 | D18: =COUNTIF(Web!B197,"Finding")+COUNTIF(Web!B198,"Finding")+COUNTIF(Web!B199,"Finding")+COUNTIF(Web!B200,"Finding")+COUNTIF(Web!B201,"Finding") -> 0 | E18: =COUNTIF(Web!B197,"Investigate")+COUNTIF(Web!B198,"Investigate")+COUNTIF(Web!B199,"Investigate")+COUNTIF(Web!B200,"Investigate")+COUNTIF(Web!B201,"Investigate") -> 0
A19: Post-Exploitation & Impact Assessment | B19: 6 | C19: =COUNTIF(Web!B204,"OK")+COUNTIF(Web!B205,"OK")+COUNTIF(Web!B206,"OK")+COUNTIF(Web!B207,"OK")+COUNTIF(Web!B208,"OK")+COUNTIF(Web!B209,"OK") -> 0 | D19: =COUNTIF(Web!B204,"Finding")+COUNTIF(Web!B205,"Finding")+COUNTIF(Web!B206,"Finding")+COUNTIF(Web!B207,"Finding")+COUNTIF(Web!B208,"Finding")+COUNTIF(Web!B209,"Finding") -> 0 | E19: =COUNTIF(Web!B204,"Investigate")+COUNTIF(Web!B205,"Investigate")+COUNTIF(Web!B206,"Investigate")+COUNTIF(Web!B207,"Investigate")+COUNTIF(Web!B208,"Investigate")+COUNTIF(Web!B209,"Investigate") -> 0
A21: Infrastructure | B21: 171 | C21: =COUNTIF(Infrastructure!B3,"OK")+COUNTIF(Infrastructure!B4,"OK")+COUNTIF(Infrastructure!B5,"OK")+COUNTIF(Infrastructure!B6,"OK")+COUNTIF(Infrastructure!B7,"OK")+COUNTIF(Infrastructure!B8,"OK")+COUNTIF(Infrastructure!B9,"OK")+COUNTIF(Infrastructure!B12,"OK")+COUNTIF(Infrastructure!B13,"OK")+COUNTIF(Infrastructure!B14,"OK")+COUNTIF(Infrastructure!B15,"OK")+COUNTIF(Infrastructure!B16,"OK")+COUNTIF(Infrastructure!B17,"OK")+COUNTIF(Infrastructure!B18,"OK")+COUNTIF(Infrastructure!B19,"OK")+COUNTIF(Infrastructure!B20,"OK")+COUNTIF(Infrastructure!B21,"OK")+COUNTIF(Infrastructure!B22,"OK")+COUNTIF(Infrastructure!B23,"OK")+COUNTIF(Infrastructure!B26,"OK")+COUNTIF(Infrastructure!B27,"OK")+COUNTIF(Infrastructure!B28,"OK")+COUNTIF(Infrastructure!B29,"OK")+COUNTIF(Infrastructure!B30,"OK")+COUNTIF(Infrastructure!B31,"OK")+COUNTIF(Infrastructure!B32,"OK")+COUNTIF(Infrastructure!B33,"OK")+COUNTIF(Infrastructure!B34,"OK")+COUNTIF(Infrastructure!B37,"OK")+COUNTIF(Infrastructure!B38,"OK")+COUNTIF(Infrastructure!B39,"OK")+COUNTIF(Infrastructure!B40,"OK")+COUNTIF(Infrastructure!B41,"OK")+COUNTIF(Infrastructure!B42,"OK")+COUNTIF(Infrastructure!B43,"OK")+COUNTIF(Infrastructure!B44,"OK")+COUNTIF(Infrastructure!B45,"OK")+COUNTIF(Infrastructure!B46,"OK")+COUNTIF(Infrastructure!B47,"OK")+COUNTIF(Infrastructure!B48,"OK")+COUNTIF(Infrastructure!B49,"OK")+COUNTIF(Infrastructure!B50,"OK")+COUNTIF(Infrastructure!B51,"OK")+COUNTIF(Infrastructure!B52,"OK")+COUNTIF(Infrastructure!B53,"OK")+COUNTIF(Infrastructure!B54,"OK")+COUNTIF(Infrastructure!B55,"OK")+COUNTIF(Infrastructure!B56,"OK")+COUNTIF(Infrastructure!B57,"OK")+COUNTIF(Infrastructure!B58,"OK")+COUNTIF(Infrastructure!B59,"OK")+COUNTIF(Infrastructure!B60,"OK")+COUNTIF(Infrastructure!B61,"OK")+COUNTIF(Infrastructure!B62,"OK")+COUNTIF(Infrastructure!B63,"OK")+COUNTIF(Infrastructure!B64,"OK")+COUNTIF(Infrastructure!B65,"OK")+COUNTIF(Infrastructure!B66,"OK")+COUNTIF(Infrastructure!B67,"OK")+COUNTIF(Infrastructure!B68,"OK")+COUNTIF(Infrastructure!B69,"OK")+COUNTIF(Infrastructure!B70,"OK")+COUNTIF(Infrastructure!B71,"OK")+COUNTIF(Infrastructure!B72,"OK")+COUNTIF(Infrastructure!B73,"OK")+COUNTIF(Infrastructure!B74,"OK")+COUNTIF(Infrastructure!B75,"OK")+COUNTIF(Infrastructure!B76,"OK")+COUNTIF(Infrastructure!B77,"OK")+COUNTIF(Infrastructure!B78,"OK")+COUNTIF(Infrastructure!B79,"OK")+COUNTIF(Infrastructure!B80,"OK")+COUNTIF(Infrastructure!B81,"OK")+COUNTIF(Infrastructure!B82,"OK")+COUNTIF(Infrastructure!B83,"OK")+COUNTIF(Infrastructure!B84,"OK")+COUNTIF(Infrastructure!B85,"OK")+COUNTIF(Infrastructure!B86,"OK")+COUNTIF(Infrastructure!B87,"OK")+COUNTIF(Infrastructure!B88,"OK")+COUNTIF(Infrastructure!B89,"OK")+COUNTIF(Infrastructure!B90,"OK")+COUNTIF(Infrastructure!B91,"OK")+COUNTIF(Infrastructure!B92,"OK")+COUNTIF(Infrastructure!B93,"OK")+COUNTIF(Infrastructure!B94,"OK")+COUNTIF(Infrastructure!B95,"OK")+COUNTIF(Infrastructure!B96,"OK")+COUNTIF(Infrastructure!B97,"OK")+COUNTIF(Infrastructure!B98,"OK")+COUNTIF(Infrastructure!B99,"OK")+COUNTIF(Infrastructure!B102,"OK")+COUNTIF(Infrastructure!B103,"OK")+COUNTIF(Infrastructure!B104,"OK")+COUNTIF(Infrastructure!B105,"OK")+COUNTIF(Infrastructure!B106,"OK")+COUNTIF(Infrastructure!B107,"OK")+COUNTIF(Infrastructure!B110,"OK")+COUNTIF(Infrastructure!B111,"OK")+COUNTIF(Infrastructure!B112,"OK")+COUNTIF(Infrastructure!B113,"OK")+COUNTIF(Infrastructure!B114,"OK")+COUNTIF(Infrastructure!B115,"OK")+COUNTIF(Infrastructure!B116,"OK")+COUNTIF(Infrastructure!B119,"OK")+COUNTIF(Infrastructure!B120,"OK")+COUNTIF(Infrastructure!B121,"OK")+COUNTIF(Infrastructure!B122,"OK")+COUNTIF(Infrastructure!B123,"OK")+COUNTIF(Infrastructure!B124,"OK")+COUNTIF(Infrastructure!B125,"OK")+COUNTIF(Infrastructure!B128,"OK")+COUNTIF(Infrastructure!B129,"OK")+COUNTIF(Infrastructure!B130,"OK")+COUNTIF(Infrastructure!B131,"OK")+COUNTIF(Infrastructure!B132,"OK")+COUNTIF(Infrastructure!B133,"OK")+COUNTIF(Infrastructure!B134,"OK")+COUNTIF(Infrastructure!B135,"OK")+COUNTIF(Infrastructure!B136,"OK")+COUNTIF(Infrastructure!B137,"OK")+COUNTIF(Infrastructure!B138,"OK")+COUNTIF(Infrastructure!B139,"OK")+COUNTIF(Infrastructure!B140,"OK")+COUNTIF(Infrastructure!B141,"OK")+COUNTIF(Infrastructure!B142,"OK")+COUNTIF(Infrastructure!B143,"OK")+COUNTIF(Infrastructure!B144,"OK")+COUNTIF(Infrastructure!B145,"OK")+COUNTIF(Infrastructure!B148,"OK")+COUNTIF(Infrastructure!B149,"OK")+COUNTIF(Infrastructure!B150,"OK")+COUNTIF(Infrastructure!B151,"OK")+COUNTIF(Infrastructure!B152,"OK")+COUNTIF(Infrastructure!B153,"OK")+COUNTIF(Infrastructure!B154,"OK")+COUNTIF(Infrastructure!B155,"OK")+COUNTIF(Infrastructure!B156,"OK")+COUNTIF(Infrastructure!B157,"OK")+COUNTIF(Infrastructure!B158,"OK")+COUNTIF(Infrastructure!B159,"OK")+COUNTIF(Infrastructure!B160,"OK")+COUNTIF(Infrastructure!B161,"OK")+COUNTIF(Infrastructure!B162,"OK")+COUNTIF(Infrastructure!B163,"OK")+COUNTIF(Infrastructure!B164,"OK")+COUNTIF(Infrastructure!B165,"OK")+COUNTIF(Infrastructure!B166,"OK")+COUNTIF(Infrastructure!B169,"OK")+COUNTIF(Infrastructure!B170,"OK")+COUNTIF(Infrastructure!B171,"OK")+COUNTIF(Infrastructure!B172,"OK")+COUNTIF(Infrastructure!B173,"OK")+COUNTIF(Infrastructure!B174,"OK")+COUNTIF(Infrastructure!B175,"OK")+COUNTIF(Infrastructure!B176,"OK")+COUNTIF(Infrastructure!B177,"OK")+COUNTIF(Infrastructure!B180,"OK")+COUNTIF(Infrastructure!B181,"OK")+COUNTIF(Infrastructure!B182,"OK")+COUNTIF(Infrastructure!B183,"OK")+COUNTIF(Infrastructure!B184,"OK")+COUNTIF(Infrastructure!B185,"OK")+COUNTIF(Infrastructure!B188,"OK")+COUNTIF(Infrastructure!B189,"OK")+COUNTIF(Infrastructure!B190,"OK")+COUNTIF(Infrastructure!B191,"OK")+COUNTIF(Infrastructure!B192,"OK")+COUNTIF(Infrastructure!B193,"OK")+COUNTIF(Infrastructure!B194,"OK")+COUNTIF(Infrastructure!B195,"OK") -> 0 | D21: =COUNTIF(Infrastructure!B3,"Finding")+COUNTIF(Infrastructure!B4,"Finding")+COUNTIF(Infrastructure!B5,"Finding")+COUNTIF(Infrastructure!B6,"Finding")+COUNTIF(Infrastructure!B7,"Finding")+COUNTIF(Infrastructure!B8,"Finding")+COUNTIF(Infrastructure!B9,"Finding")+COUNTIF(Infrastructure!B12,"Finding")+COUNTIF(Infrastructure!B13,"Finding")+COUNTIF(Infrastructure!B14,"Finding")+COUNTIF(Infrastructure!B15,"Finding")+COUNTIF(Infrastructure!B16,"Finding")+COUNTIF(Infrastructure!B17,"Finding")+COUNTIF(Infrastructure!B18,"Finding")+COUNTIF(Infrastructure!B19,"Finding")+COUNTIF(Infrastructure!B20,"Finding")+COUNTIF(Infrastructure!B21,"Finding")+COUNTIF(Infrastructure!B22,"Finding")+COUNTIF(Infrastructure!B23,"Finding")+COUNTIF(Infrastructure!B26,"Finding")+COUNTIF(Infrastructure!B27,"Finding")+COUNTIF(Infrastructure!B28,"Finding")+COUNTIF(Infrastructure!B29,"Finding")+COUNTIF(Infrastructure!B30,"Finding")+COUNTIF(Infrastructure!B31,"Finding")+COUNTIF(Infrastructure!B32,"Finding")+COUNTIF(Infrastructure!B33,"Finding")+COUNTIF(Infrastructure!B34,"Finding")+COUNTIF(Infrastructure!B37,"Finding")+COUNTIF(Infrastructure!B38,"Finding")+COUNTIF(Infrastructure!B39,"Finding")+COUNTIF(Infrastructure!B40,"Finding")+COUNTIF(Infrastructure!B41,"Finding")+COUNTIF(Infrastructure!B42,"Finding")+COUNTIF(Infrastructure!B43,"Finding")+COUNTIF(Infrastructure!B44,"Finding")+COUNTIF(Infrastructure!B45,"Finding")+COUNTIF(Infrastructure!B46,"Finding")+COUNTIF(Infrastructure!B47,"Finding")+COUNTIF(Infrastructure!B48,"Finding")+COUNTIF(Infrastructure!B49,"Finding")+COUNTIF(Infrastructure!B50,"Finding")+COUNTIF(Infrastructure!B51,"Finding")+COUNTIF(Infrastructure!B52,"Finding")+COUNTIF(Infrastructure!B53,"Finding")+COUNTIF(Infrastructure!B54,"Finding")+COUNTIF(Infrastructure!B55,"Finding")+COUNTIF(Infrastructure!B56,"Finding")+COUNTIF(Infrastructure!B57,"Finding")+COUNTIF(Infrastructure!B58,"Finding")+COUNTIF(Infrastructure!B59,"Finding")+COUNTIF(Infrastructure!B60,"Finding")+COUNTIF(Infrastructure!B61,"Finding")+COUNTIF(Infrastructure!B62,"Finding")+COUNTIF(Infrastructure!B63,"Finding")+COUNTIF(Infrastructure!B64,"Finding")+COUNTIF(Infrastructure!B65,"Finding")+COUNTIF(Infrastructure!B66,"Finding")+COUNTIF(Infrastructure!B67,"Finding")+COUNTIF(Infrastructure!B68,"Finding")+COUNTIF(Infrastructure!B69,"Finding")+COUNTIF(Infrastructure!B70,"Finding")+COUNTIF(Infrastructure!B71,"Finding")+COUNTIF(Infrastructure!B72,"Finding")+COUNTIF(Infrastructure!B73,"Finding")+COUNTIF(Infrastructure!B74,"Finding")+COUNTIF(Infrastructure!B75,"Finding")+COUNTIF(Infrastructure!B76,"Finding")+COUNTIF(Infrastructure!B77,"Finding")+COUNTIF(Infrastructure!B78,"Finding")+COUNTIF(Infrastructure!B79,"Finding")+COUNTIF(Infrastructure!B80,"Finding")+COUNTIF(Infrastructure!B81,"Finding")+COUNTIF(Infrastructure!B82,"Finding")+COUNTIF(Infrastructure!B83,"Finding")+COUNTIF(Infrastructure!B84,"Finding")+COUNTIF(Infrastructure!B85,"Finding")+COUNTIF(Infrastructure!B86,"Finding")+COUNTIF(Infrastructure!B87,"Finding")+COUNTIF(Infrastructure!B88,"Finding")+COUNTIF(Infrastructure!B89,"Finding")+COUNTIF(Infrastructure!B90,"Finding")+COUNTIF(Infrastructure!B91,"Finding")+COUNTIF(Infrastructure!B92,"Finding")+COUNTIF(Infrastructure!B93,"Finding")+COUNTIF(Infrastructure!B94,"Finding")+COUNTIF(Infrastructure!B95,"Finding")+COUNTIF(Infrastructure!B96,"Finding")+COUNTIF(Infrastructure!B97,"Finding")+COUNTIF(Infrastructure!B98,"Finding")+COUNTIF(Infrastructure!B99,"Finding")+COUNTIF(Infrastructure!B102,"Finding")+COUNTIF(Infrastructure!B103,"Finding")+COUNTIF(Infrastructure!B104,"Finding")+COUNTIF(Infrastructure!B105,"Finding")+COUNTIF(Infrastructure!B106,"Finding")+COUNTIF(Infrastructure!B107,"Finding")+COUNTIF(Infrastructure!B110,"Finding")+COUNTIF(Infrastructure!B111,"Finding")+COUNTIF(Infrastructure!B112,"Finding")+COUNTIF(Infrastructure!B113,"Finding")+COUNTIF(Infrastructure!B114,"Finding")+COUNTIF(Infrastructure!B115,"Finding")+COUNTIF(Infrastructure!B116,"Finding")+COUNTIF(Infrastructure!B119,"Finding")+COUNTIF(Infrastructure!B120,"Finding")+COUNTIF(Infrastructure!B121,"Finding")+COUNTIF(Infrastructure!B122,"Finding")+COUNTIF(Infrastructure!B123,"Finding")+COUNTIF(Infrastructure!B124,"Finding")+COUNTIF(Infrastructure!B125,"Finding")+COUNTIF(Infrastructure!B128,"Finding")+COUNTIF(Infrastructure!B129,"Finding")+COUNTIF(Infrastructure!B130,"Finding")+COUNTIF(Infrastructure!B131,"Finding")+COUNTIF(Infrastructure!B132,"Finding")+COUNTIF(Infrastructure!B133,"Finding")+COUNTIF(Infrastructure!B134,"Finding")+COUNTIF(Infrastructure!B135,"Finding")+COUNTIF(Infrastructure!B136,"Finding")+COUNTIF(Infrastructure!B137,"Finding")+COUNTIF(Infrastructure!B138,"Finding")+COUNTIF(Infrastructure!B139,"Finding")+COUNTIF(Infrastructure!B140,"Finding")+COUNTIF(Infrastructure!B141,"Finding")+COUNTIF(Infrastructure!B142,"Finding")+COUNTIF(Infrastructure!B143,"Finding")+COUNTIF(Infrastructure!B144,"Finding")+COUNTIF(Infrastructure!B145,"Finding")+COUNTIF(Infrastructure!B148,"Finding")+COUNTIF(Infrastructure!B149,"Finding")+COUNTIF(Infrastructure!B150,"Finding")+COUNTIF(Infrastructure!B151,"Finding")+COUNTIF(Infrastructure!B152,"Finding")+COUNTIF(Infrastructure!B153,"Finding")+COUNTIF(Infrastructure!B154,"Finding")+COUNTIF(Infrastructure!B155,"Finding")+COUNTIF(Infrastructure!B156,"Finding")+COUNTIF(Infrastructure!B157,"Finding")+COUNTIF(Infrastructure!B158,"Finding")+COUNTIF(Infrastructure!B159,"Finding")+COUNTIF(Infrastructure!B160,"Finding")+COUNTIF(Infrastructure!B161,"Finding")+COUNTIF(Infrastructure!B162,"Finding")+COUNTIF(Infrastructure!B163,"Finding")+COUNTIF(Infrastructure!B164,"Finding")+COUNTIF(Infrastructure!B165,"Finding")+COUNTIF(Infrastructure!B166,"Finding")+COUNTIF(Infrastructure!B169,"Finding")+COUNTIF(Infrastructure!B170,"Finding")+COUNTIF(Infrastructure!B171,"Finding")+COUNTIF(Infrastructure!B172,"Finding")+COUNTIF(Infrastructure!B173,"Finding")+COUNTIF(Infrastructure!B174,"Finding")+COUNTIF(Infrastructure!B175,"Finding")+COUNTIF(Infrastructure!B176,"Finding")+COUNTIF(Infrastructure!B177,"Finding")+COUNTIF(Infrastructure!B180,"Finding")+COUNTIF(Infrastructure!B181,"Finding")+COUNTIF(Infrastructure!B182,"Finding")+COUNTIF(Infrastructure!B183,"Finding")+COUNTIF(Infrastructure!B184,"Finding")+COUNTIF(Infrastructure!B185,"Finding")+COUNTIF(Infrastructure!B188,"Finding")+COUNTIF(Infrastructure!B189,"Finding")+COUNTIF(Infrastructure!B190,"Finding")+COUNTIF(Infrastructure!B191,"Finding")+COUNTIF(Infrastructure!B192,"Finding")+COUNTIF(Infrastructure!B193,"Finding")+COUNTIF(Infrastructure!B194,"Finding")+COUNTIF(Infrastructure!B195,"Finding") -> 0 | E21: =COUNTIF(Infrastructure!B3,"Investigate")+COUNTIF(Infrastructure!B4,"Investigate")+COUNTIF(Infrastructure!B5,"Investigate")+COUNTIF(Infrastructure!B6,"Investigate")+COUNTIF(Infrastructure!B7,"Investigate")+COUNTIF(Infrastructure!B8,"Investigate")+COUNTIF(Infrastructure!B9,"Investigate")+COUNTIF(Infrastructure!B12,"Investigate")+COUNTIF(Infrastructure!B13,"Investigate")+COUNTIF(Infrastructure!B14,"Investigate")+COUNTIF(Infrastructure!B15,"Investigate")+COUNTIF(Infrastructure!B16,"Investigate")+COUNTIF(Infrastructure!B17,"Investigate")+COUNTIF(Infrastructure!B18,"Investigate")+COUNTIF(Infrastructure!B19,"Investigate")+COUNTIF(Infrastructure!B20,"Investigate")+COUNTIF(Infrastructure!B21,"Investigate")+COUNTIF(Infrastructure!B22,"Investigate")+COUNTIF(Infrastructure!B23,"Investigate")+COUNTIF(Infrastructure!B26,"Investigate")+COUNTIF(Infrastructure!B27,"Investigate")+COUNTIF(Infrastructure!B28,"Investigate")+COUNTIF(Infrastructure!B29,"Investigate")+COUNTIF(Infrastructure!B30,"Investigate")+COUNTIF(Infrastructure!B31,"Investigate")+COUNTIF(Infrastructure!B32,"Investigate")+COUNTIF(Infrastructure!B33,"Investigate")+COUNTIF(Infrastructure!B34,"Investigate")+COUNTIF(Infrastructure!B37,"Investigate")+COUNTIF(Infrastructure!B38,"Investigate")+COUNTIF(Infrastructure!B39,"Investigate")+COUNTIF(Infrastructure!B40,"Investigate")+COUNTIF(Infrastructure!B41,"Investigate")+COUNTIF(Infrastructure!B42,"Investigate")+COUNTIF(Infrastructure!B43,"Investigate")+COUNTIF(Infrastructure!B44,"Investigate")+COUNTIF(Infrastructure!B45,"Investigate")+COUNTIF(Infrastructure!B46,"Investigate")+COUNTIF(Infrastructure!B47,"Investigate")+COUNTIF(Infrastructure!B48,"Investigate")+COUNTIF(Infrastructure!B49,"Investigate")+COUNTIF(Infrastructure!B50,"Investigate")+COUNTIF(Infrastructure!B51,"Investigate")+COUNTIF(Infrastructure!B52,"Investigate")+COUNTIF(Infrastructure!B53,"Investigate")+COUNTIF(Infrastructure!B54,"Investigate")+COUNTIF(Infrastructure!B55,"Investigate")+COUNTIF(Infrastructure!B56,"Investigate")+COUNTIF(Infrastructure!B57,"Investigate")+COUNTIF(Infrastructure!B58,"Investigate")+COUNTIF(Infrastructure!B59,"Investigate")+COUNTIF(Infrastructure!B60,"Investigate")+COUNTIF(Infrastructure!B61,"Investigate")+COUNTIF(Infrastructure!B62,"Investigate")+COUNTIF(Infrastructure!B63,"Investigate")+COUNTIF(Infrastructure!B64,"Investigate")+COUNTIF(Infrastructure!B65,"Investigate")+COUNTIF(Infrastructure!B66,"Investigate")+COUNTIF(Infrastructure!B67,"Investigate")+COUNTIF(Infrastructure!B68,"Investigate")+COUNTIF(Infrastructure!B69,"Investigate")+COUNTIF(Infrastructure!B70,"Investigate")+COUNTIF(Infrastructure!B71,"Investigate")+COUNTIF(Infrastructure!B72,"Investigate")+COUNTIF(Infrastructure!B73,"Investigate")+COUNTIF(Infrastructure!B74,"Investigate")+COUNTIF(Infrastructure!B75,"Investigate")+COUNTIF(Infrastructure!B76,"Investigate")+COUNTIF(Infrastructure!B77,"Investigate")+COUNTIF(Infrastructure!B78,"Investigate")+COUNTIF(Infrastructure!B79,"Investigate")+COUNTIF(Infrastructure!B80,"Investigate")+COUNTIF(Infrastructure!B81,"Investigate")+COUNTIF(Infrastructure!B82,"Investigate")+COUNTIF(Infrastructure!B83,"Investigate")+COUNTIF(Infrastructure!B84,"Investigate")+COUNTIF(Infrastructure!B85,"Investigate")+COUNTIF(Infrastructure!B86,"Investigate")+COUNTIF(Infrastructure!B87,"Investigate")+COUNTIF(Infrastructure!B88,"Investigate")+COUNTIF(Infrastructure!B89,"Investigate")+COUNTIF(Infrastructure!B90,"Investigate")+COUNTIF(Infrastructure!B91,"Investigate")+COUNTIF(Infrastructure!B92,"Investigate")+COUNTIF(Infrastructure!B93,"Investigate")+COUNTIF(Infrastructure!B94,"Investigate")+COUNTIF(Infrastructure!B95,"Investigate")+COUNTIF(Infrastructure!B96,"Investigate")+COUNTIF(Infrastructure!B97,"Investigate")+COUNTIF(Infrastructure!B98,"Investigate")+COUNTIF(Infrastructure!B99,"Investigate")+COUNTIF(Infrastructure!B102,"Investigate")+COUNTIF(Infrastructure!B103,"Investigate")+COUNTIF(Infrastructure!B104,"Investigate")+COUNTIF(Infrastructure!B105,"Investigate")+COUNTIF(Infrastructure!B106,"Investigate")+COUNTIF(Infrastructure!B107,"Investigate")+COUNTIF(Infrastructure!B110,"Investigate")+COUNTIF(Infrastructure!B111,"Investigate")+COUNTIF(Infrastructure!B112,"Investigate")+COUNTIF(Infrastructure!B113,"Investigate")+COUNTIF(Infrastructure!B114,"Investigate")+COUNTIF(Infrastructure!B115,"Investigate")+COUNTIF(Infrastructure!B116,"Investigate")+COUNTIF(Infrastructure!B119,"Investigate")+COUNTIF(Infrastructure!B120,"Investigate")+COUNTIF(Infrastructure!B121,"Investigate")+COUNTIF(Infrastructure!B122,"Investigate")+COUNTIF(Infrastructure!B123,"Investigate")+COUNTIF(Infrastructure!B124,"Investigate")+COUNTIF(Infrastructure!B125,"Investigate")+COUNTIF(Infrastructure!B128,"Investigate")+COUNTIF(Infrastructure!B129,"Investigate")+COUNTIF(Infrastructure!B130,"Investigate")+COUNTIF(Infrastructure!B131,"Investigate")+COUNTIF(Infrastructure!B132,"Investigate")+COUNTIF(Infrastructure!B133,"Investigate")+COUNTIF(Infrastructure!B134,"Investigate")+COUNTIF(Infrastructure!B135,"Investigate")+COUNTIF(Infrastructure!B136,"Investigate")+COUNTIF(Infrastructure!B137,"Investigate")+COUNTIF(Infrastructure!B138,"Investigate")+COUNTIF(Infrastructure!B139,"Investigate")+COUNTIF(Infrastructure!B140,"Investigate")+COUNTIF(Infrastructure!B141,"Investigate")+COUNTIF(Infrastructure!B142,"Investigate")+COUNTIF(Infrastructure!B143,"Investigate")+COUNTIF(Infrastructure!B144,"Investigate")+COUNTIF(Infrastructure!B145,"Investigate")+COUNTIF(Infrastructure!B148,"Investigate")+COUNTIF(Infrastructure!B149,"Investigate")+COUNTIF(Infrastructure!B150,"Investigate")+COUNTIF(Infrastructure!B151,"Investigate")+COUNTIF(Infrastructure!B152,"Investigate")+COUNTIF(Infrastructure!B153,"Investigate")+COUNTIF(Infrastructure!B154,"Investigate")+COUNTIF(Infrastructure!B155,"Investigate")+COUNTIF(Infrastructure!B156,"Investigate")+COUNTIF(Infrastructure!B157,"Investigate")+COUNTIF(Infrastructure!B158,"Investigate")+COUNTIF(Infrastructure!B159,"Investigate")+COUNTIF(Infrastructure!B160,"Investigate")+COUNTIF(Infrastructure!B161,"Investigate")+COUNTIF(Infrastructure!B162,"Investigate")+COUNTIF(Infrastructure!B163,"Investigate")+COUNTIF(Infrastructure!B164,"Investigate")+COUNTIF(Infrastructure!B165,"Investigate")+COUNTIF(Infrastructure!B166,"Investigate")+COUNTIF(Infrastructure!B169,"Investigate")+COUNTIF(Infrastructure!B170,"Investigate")+COUNTIF(Infrastructure!B171,"Investigate")+COUNTIF(Infrastructure!B172,"Investigate")+COUNTIF(Infrastructure!B173,"Investigate")+COUNTIF(Infrastructure!B174,"Investigate")+COUNTIF(Infrastructure!B175,"Investigate")+COUNTIF(Infrastructure!B176,"Investigate")+COUNTIF(Infrastructure!B177,"Investigate")+COUNTIF(Infrastructure!B180,"Investigate")+COUNTIF(Infrastructure!B181,"Investigate")+COUNTIF(Infrastructure!B182,"Investigate")+COUNTIF(Infrastructure!B183,"Investigate")+COUNTIF(Infrastructure!B184,"Investigate")+COUNTIF(Infrastructure!B185,"Investigate")+COUNTIF(Infrastructure!B188,"Investigate")+COUNTIF(Infrastructure!B189,"Investigate")+COUNTIF(Infrastructure!B190,"Investigate")+COUNTIF(Infrastructure!B191,"Investigate")+COUNTIF(Infrastructure!B192,"Investigate")+COUNTIF(Infrastructure!B193,"Investigate")+COUNTIF(Infrastructure!B194,"Investigate")+COUNTIF(Infrastructure!B195,"Investigate") -> 0
A22: Pre-Engagement & Scoping | B22: 7 | C22: =COUNTIF(Infrastructure!B3,"OK")+COUNTIF(Infrastructure!B4,"OK")+COUNTIF(Infrastructure!B5,"OK")+COUNTIF(Infrastructure!B6,"OK")+COUNTIF(Infrastructure!B7,"OK")+COUNTIF(Infrastructure!B8,"OK")+COUNTIF(Infrastructure!B9,"OK") -> 0 | D22: =COUNTIF(Infrastructure!B3,"Finding")+COUNTIF(Infrastructure!B4,"Finding")+COUNTIF(Infrastructure!B5,"Finding")+COUNTIF(Infrastructure!B6,"Finding")+COUNTIF(Infrastructure!B7,"Finding")+COUNTIF(Infrastructure!B8,"Finding")+COUNTIF(Infrastructure!B9,"Finding") -> 0 | E22: =COUNTIF(Infrastructure!B3,"Investigate")+COUNTIF(Infrastructure!B4,"Investigate")+COUNTIF(Infrastructure!B5,"Investigate")+COUNTIF(Infrastructure!B6,"Investigate")+COUNTIF(Infrastructure!B7,"Investigate")+COUNTIF(Infrastructure!B8,"Investigate")+COUNTIF(Infrastructure!B9,"Investigate") -> 0
A23: External Reconnaissance (OSINT) | B23: 12 | C23: =COUNTIF(Infrastructure!B12,"OK")+COUNTIF(Infrastructure!B13,"OK")+COUNTIF(Infrastructure!B14,"OK")+COUNTIF(Infrastructure!B15,"OK")+COUNTIF(Infrastructure!B16,"OK")+COUNTIF(Infrastructure!B17,"OK")+COUNTIF(Infrastructure!B18,"OK")+COUNTIF(Infrastructure!B19,"OK")+COUNTIF(Infrastructure!B20,"OK")+COUNTIF(Infrastructure!B21,"OK")+COUNTIF(Infrastructure!B22,"OK")+COUNTIF(Infrastructure!B23,"OK") -> 0 | D23: =COUNTIF(Infrastructure!B12,"Finding")+COUNTIF(Infrastructure!B13,"Finding")+COUNTIF(Infrastructure!B14,"Finding")+COUNTIF(Infrastructure!B15,"Finding")+COUNTIF(Infrastructure!B16,"Finding")+COUNTIF(Infrastructure!B17,"Finding")+COUNTIF(Infrastructure!B18,"Finding")+COUNTIF(Infrastructure!B19,"Finding")+COUNTIF(Infrastructure!B20,"Finding")+COUNTIF(Infrastructure!B21,"Finding")+COUNTIF(Infrastructure!B22,"Finding")+COUNTIF(Infrastructure!B23,"Finding") -> 0 | E23: =COUNTIF(Infrastructure!B12,"Investigate")+COUNTIF(Infrastructure!B13,"Investigate")+COUNTIF(Infrastructure!B14,"Investigate")+COUNTIF(Infrastructure!B15,"Investigate")+COUNTIF(Infrastructure!B16,"Investigate")+COUNTIF(Infrastructure!B17,"Investigate")+COUNTIF(Infrastructure!B18,"Investigate")+COUNTIF(Infrastructure!B19,"Investigate")+COUNTIF(Infrastructure!B20,"Investigate")+COUNTIF(Infrastructure!B21,"Investigate")+COUNTIF(Infrastructure!B22,"Investigate")+COUNTIF(Infrastructure!B23,"Investigate") -> 0
A24: Network Scanning & Enumeration | B24: 9 | C24: =COUNTIF(Infrastructure!B26,"OK")+COUNTIF(Infrastructure!B27,"OK")+COUNTIF(Infrastructure!B28,"OK")+COUNTIF(Infrastructure!B29,"OK")+COUNTIF(Infrastructure!B30,"OK")+COUNTIF(Infrastructure!B31,"OK")+COUNTIF(Infrastructure!B32,"OK")+COUNTIF(Infrastructure!B33,"OK")+COUNTIF(Infrastructure!B34,"OK") -> 0 | D24: =COUNTIF(Infrastructure!B26,"Finding")+COUNTIF(Infrastructure!B27,"Finding")+COUNTIF(Infrastructure!B28,"Finding")+COUNTIF(Infrastructure!B29,"Finding")+COUNTIF(Infrastructure!B30,"Finding")+COUNTIF(Infrastructure!B31,"Finding")+COUNTIF(Infrastructure!B32,"Finding")+COUNTIF(Infrastructure!B33,"Finding")+COUNTIF(Infrastructure!B34,"Finding") -> 0 | E24: =COUNTIF(Infrastructure!B26,"Investigate")+COUNTIF(Infrastructure!B27,"Investigate")+COUNTIF(Infrastructure!B28,"Investigate")+COUNTIF(Infrastructure!B29,"Investigate")+COUNTIF(Infrastructure!B30,"Investigate")+COUNTIF(Infrastructure!B31,"Investigate")+COUNTIF(Infrastructure!B32,"Investigate")+COUNTIF(Infrastructure!B33,"Investigate")+COUNTIF(Infrastructure!B34,"Investigate") -> 0
